Workbook

Sheet Folha3
A1: Pedido | B1: Data de Vencimento | C1: Cliente | D1: Email | E1: Telefone | F1: Produto | G1: Ponto de Atendimento | H1: Agente | I1: Status do Pedido | J1: CPF | K1: CNPJ | L1: Razão Social
A2: =Transferencia!A2 -> 19993515 | B2: =Transferencia!B2 -> 01/02/2025 | C2: =Transferencia!C2 -> GUSTAVO CORONADO SILVA | D2: =Transferencia!D2 -> DANUSIA@SMCONSUL.COM.BR | E2: =Transferencia!G2 -> 5511940346464 | F2: =Transferencia!H2 -> e-CNPJ A3 - 3 anos - PME | G2: =Transferencia!J2 -> Ponto de Atendimento AR Certifast - Pauliceia/SP | H2: =VLOOKUP(G2,Página1!G:L,6,0) -> Alexandre | I2: Aprovado | J2: =Transferencia!L2 -> 487.045.518-85 | K2: =Transferencia!M2 -> 24.020.767/0001-40 | L2: =Transferencia!N2 -> GMUD SERVICOS E INFORMATICA EIRELI
A3: =Transferencia!A3 -> 19998399 | B3: =Transferencia!B3 -> 01/02/2025 | C3: =Transferencia!C3 -> ISABELA PORTO NASCIMENTO | D3: =Transferencia!D3 -> isabela.nascimento@tjmg.jus.br | E3: =Transferencia!G3 -> 5531975539005 | F3: =Transferencia!H3 -> e-CPF A3 - 3 anos | G3: =Transferencia!J3 -> Ponto de Atendimento AR Certifast - Prado BH/MG - JUS | H3: =VLOOKUP(G3,Página1!G:L,6,0) -> Isabella | I3: Aprovado | J3: =Transferencia!L3 -> 874.483.271-00 | K3: =Transferencia!M3
A4: =Transferencia!A4 -> 20008751 | B4: =Transferencia!B4 -> 01/02/2025 | C4: =Transferencia!C4 -> CLAUDIO LUIZ CARVALHO SOUZA | D4: =Transferencia!D4 -> claudio@engenhariapower.com.br | E4: =Transferencia!G4 -> 551230185487 | F4: =Transferencia!H4 -> e-CPF A3 - 3 anos | G4: =Transferencia!J4 -> PONTO DE ATENDIMENTO AR CERTIFAST - ANDROMEDA/SP | H4: =VLOOKUP(G4,Página1!G:L,6,0) -> Rogério | I4: Aprovado | J4: =Transferencia!L4 -> 027.312.736-58 | K4: =Transferencia!M4
A5: =Transferencia!A5 -> 22904676 | B5: =Transferencia!B5 -> 01/02/2025 | C5: =Transferencia!C5 -> EDMUNDO MARIANO DA COSTA LANNA | D5: =Transferencia!D5 -> contabilidade@cimcop.com.br | E5: =Transferencia!G5 -> 5531991665091 | F5: =Transferencia!H5 -> e-CNPJ A1 - 1 ano | G5: =Transferencia!J5 -> Ponto de Atendimento AR Certifast - Prado BH/MG | H5: =VLOOKUP(G5,Página1!G:L,6,0) -> Isabella | I5: Aprovado | J5: =Transferencia!L5 -> 522.536.866-20 | K5: =Transferencia!M5 -> 17.161.464/0001-82
A6: =Transferencia!A6 -> 22925222 | B6: =Transferencia!B6 -> 01/02/2025 | C6: =Transferencia!C6 -> MARIA GISELE CRUZ ANDRADE | D6: =Transferencia!D6 -> adm.monteferragens@gmail.com | E6: =Transferencia!G6 -> 5511939391930 | F6: =Transferencia!H6 -> e-CNPJ A1 - 1 ano | G6: =Transferencia!J6 -> Ponto de Atendimento AR Certifast - Maua Centro/SP | H6: =VLOOKUP(G6,Página1!G:L,6,0) -> Ingrid | I6: Aprovado | J6: =Transferencia!L6 -> 401.065.218-70 | K6: =Transferencia!M6 -> 49.393.402/0001-92
A7: =Transferencia!A7 -> 22978910 | B7: =Transferencia!B7 -> 01/02/2025 | C7: =Transferencia!C7 -> RAFAEL RODRIGUES DE MELO | D7: =Transferencia!D7 -> jh.contabilidade@hotmail.com | E7: =Transferencia!G7 -> 5511984111572 | F7: =Transferencia!H7 -> e-CNPJ A1 - PME | G7: =Transferencia!J7 -> PONTO DE ATENDIMENTO AR CERTIFAST - ANDROMEDA/SP | H7: =VLOOKUP(G7,Página1!G:L,6,0) -> Rogério | I7: Aprovado | J7: =Transferencia!L7 -> 348.833.098-27 | K7: =Transferencia!M7 -> 53.594.729/0001-08
A8: =Transferencia!A8 -> 23000204 | B8: =Transferencia!B8 -> 01/02/2025 | C8: =Transferencia!C8 -> WALTER SILVEIRA | D8: =Transferencia!D8 -> coord.societario@reluzcontabil.com.br | E8: =Transferencia!G8 -> 5511998586363 | F8: =Transferencia!H8 -> e-CNPJ A1 - PME | G8: =Transferencia!J8 -> Ponto de Atendimento AR Certifast - Maua Centro/SP | H8: =VLOOKUP(G8,Página1!G:L,6,0) -> Ingrid | I8: Aprovado | J8: =Transferencia!L8 -> 614.447.588-53 | K8: =Transferencia!M8 -> 39.378.578/0002-00
A9: =Transferencia!A9 -> 23005642 | B9: =Transferencia!B9 -> 01/02/2025 | C9: =Transferencia!C9 -> EMERSON LUIS TEIXEIRA | D9: =Transferencia!D9 -> brenda.bulgarelli@biocontabil.com.br | E9: =Transferencia!G9 -> 5511996005678 | F9: =Transferencia!H9 -> e-CNPJ A1 - PME | G9: =Transferencia!J9 -> PONTO DE ATENDIMENTO AR CERTIFAST - ANDROMEDA/SP | H9: =VLOOKUP(G9,Página1!G:L,6,0) -> Rogério | I9: Aprovado | J9: =Transferencia!L9 -> 139.953.418-10 | K9: =Transferencia!M9 -> 19.005.929/0001-31
A10: =Transferencia!A10 -> 23009504 | B10: =Transferencia!B10 -> 01/02/2025 | C10: =Transferencia!C10 -> ADALBERTO FERREIRA FILHO | D10: =Transferencia!D10 -> brun31ma@terra.com.br | E10: =Transferencia!G10 -> 55 | F10: =Transferencia!H10 -> e-CNPJ A1 - PME | G10: =Transferencia!J10 -> Ponto de Atendimento AR Certifast - Maua Centro/SP | H10: =VLOOKUP(G10,Página1!G:L,6,0) -> Ingrid | I10: Aprovado | J10: =Transferencia!L10 -> 008.226.258-65 | K10: =Transferencia!M10 -> 35.524.722/0001-20
A11: =Transferencia!A11 -> 23013368 | B11: =Transferencia!B11 -> 01/02/2025 | C11: =Transferencia!C11 -> HUGO CARDOSO GONCALVES PEREIRA | D11: =Transferencia!D11 -> goncalves.hugo@outlook.com | E11: =Transferencia!G11 -> 5511949407981 | F11: =Transferencia!H11 -> e-CNPJ A1 - 1 ano | G11: =Transferencia!J11 -> Ponto de Atendimento AR Certifast - Maua Centro/SP | H11: =VLOOKUP(G11,Página1!G:L,6,0) -> Ingrid | I11: Aprovado | J11: =Transferencia!L11 -> 403.679.028-50 | K11: =Transferencia!M11 -> 37.403.134/0001-63
A12: =Transferencia!A12 -> 23014736 | B12: =Transferencia!B12 -> 01/02/2025 | C12: =Transferencia!C12 -> DAYANE ONILES BATISTA DA SILVA | D12: =Transferencia!D12 -> dayane.obs@gmail.com | E12: =Transferencia!G12 -> 55 | F12: =Transferencia!H12 -> e-CNPJ A1 - 1 ano | G12: =Transferencia!J12 -> Ponto de Atendimento AR Certifast - Maua Centro/SP | H12: =VLOOKUP(G12,Página1!G:L,6,0) -> Ingrid | I12: Aprovado | J12: =Transferencia!L12 -> 375.947.258-32 | K12: =Transferencia!M12 -> 46.138.623/0001-26
A13: =Transferencia!A13 -> 23018988 | B13: =Transferencia!B13 -> 01/02/2025 | C13: =Transferencia!C13 -> ALBERTO SIQUEIRA FERREIRA | D13: =Transferencia!D13 -> albertosq@gmail.com | E13: =Transferencia!G13 -> 55 | F13: =Transferencia!H13 -> e-CNPJ A1 - PME | G13: =Transferencia!J13 -> Ponto de Atendimento AR Certifast - Maua Centro/SP | H13: =VLOOKUP(G13,Página1!G:L,6,0) -> Ingrid | I13: Aprovado | J13: =Transferencia!L13 -> 377.932.518-73 | K13: =Transferencia!M13 -> 37.005.872/0001-52 | L13: D DE S DIAS
A14: =Transferencia!A14 -> 23021199 | B14: =Transferencia!B14 -> 01/02/2025 | C14: =Transferencia!C14 -> AGENILTO ALVES DA CRUZ | D14: =Transferencia!D14 -> coord.societario@reluzcontabil.com.br | E14: =Transferencia!G14 -> 5511971486400 | F14: =Transferencia!H14 -> e-CPF A1 - 1 ano | G14: =Transferencia!J14 -> Ponto de Atendimento AR Certifast - Maua Centro/SP | H14: =VLOOKUP(G14,Página1!G:L,6,0) -> Ingrid | I14: Aprovado | J14: =Transferencia!L14 -> 182.969.108-29 | K14: =Transferencia!M14 | L14: SOLUTION SITES SOLUCAO INFORMATIZADA LTDA
A15: =Transferencia!A15 -> 23022711 | B15: =Transferencia!B15 -> 01/02/2025 | C15: =Transferencia!C15 -> ANA PAULA OJEDA DE OLIVEIRA | D15: =Transferencia!D15 -> coord.societario@reluzcontabil.com.br | E15: =Transferencia!G15 -> 5511911445032 | F15: =Transferencia!H15 -> e-CPF A1 - 1 ano | G15: =Transferencia!J15 -> Ponto de Atendimento AR Certifast - Maua Centro/SP | H15: =VLOOKUP(G15,Página1!G:L,6,0) -> Ingrid | I15: Aprovado | J15: =Transferencia!L15 -> 221.613.368-00 | K15: =Transferencia!M15
A16: =Transferencia!A16 -> 23023472 | B16: =Transferencia!B16 -> 01/02/2025 | C16: =Transferencia!C16 -> MARCEL SANT ANA GUARIENTE | D16: =Transferencia!D16 -> marcel.guariente@gmail.com | E16: =Transferencia!G16 -> 55 | F16: =Transferencia!H16 -> e-CPF A1 - 1 ano | G16: =Transferencia!J16 -> Ponto de Atendimento AR Certifast - Maua Centro/SP | H16: =VLOOKUP(G16,Página1!G:L,6,0) -> Ingrid | I16: Aprovado | J16: =Transferencia!L16 -> 410.216.078-78 | K16: =Transferencia!M16
A17: =Transferencia!A17 -> 23026458 | B17: =Transferencia!B17 -> 01/02/2025 | C17: =Transferencia!C17 -> ADALTO LOURENCO SANTOS | D17: =Transferencia!D17 -> coord.societario@reluzcontabil.com.br | E17: =Transferencia!G17 -> 5513997174553 | F17: =Transferencia!H17 -> e-CNPJ A1 - PME | G17: =Transferencia!J17 -> Ponto de Atendimento AR Certifast - Maua Centro/SP | H17: =VLOOKUP(G17,Página1!G:L,6,0) -> Ingrid | I17: Aprovado | J17: =Transferencia!L17 -> 289.509.778-00 | K17: =Transferencia!M17 -> 32.147.600/0001-73 | L17: NEUSA LIMA DE OLIVEIRA DA SILVA 26970247864
A18: =Transferencia!A18 -> 23026909 | B18: =Transferencia!B18 -> 01/02/2025 | C18: =Transferencia!C18 -> GISLAINE MARTINS | D18: =Transferencia!D18 -> contabilidade2@escritoriocontabiletica.com.br | E18: =Transferencia!G18 -> 55 | F18: =Transferencia!H18 -> e-CNPJ A1 - 1 ano | G18: =Transferencia!J18 -> Ponto de Atendimento AR Certifast - Maua Centro/SP | H18: =VLOOKUP(G18,Página1!G:L,6,0) -> Ingrid | I18: Aprovado | J18: =Transferencia!L18 -> 170.433.338-57 | K18: =Transferencia!M18 -> 10.994.130/0001-40 | L18: REPRESENTACOES J SILVA LTDA
A19: =Transferencia!A19 -> 23027103 | B19: =Transferencia!B19 -> 01/02/2025 | C19: =Transferencia!C19 -> JOSE FABIO NETTO PARENTONI | D19: =Transferencia!D19 -> henriquepedrosa@madeplan.com.br | E19: =Transferencia!G19 -> 5531989014897 | F19: =Transferencia!H19 -> e-CNPJ A1 - 1 ano | G19: =Transferencia!J19 -> Ponto de Atendimento AR Certifast - Prado BH/MG | H19: =VLOOKUP(G19,Página1!G:L,6,0) -> Isabella | I19: Aprovado | J19: =Transferencia!L19 -> 500.784.886-72 | K19: =Transferencia!M19 -> 21.097.712/0001-40 | L19: RONECAL METAIS LTDA
A20: =Transferencia!A20 -> 23028744 | B20: =Transferencia!B20 -> 01/02/2025 | C20: =Transferencia!C20 -> LEANDRO CUNHA LOBO | D20: =Transferencia!D20 -> coord.societario@reluzcontabil.com.br | E20: =Transferencia!G20 -> 5511947888348 | F20: =Transferencia!H20 -> e-CNPJ A1 - PME | G20: =Transferencia!J20 -> Ponto de Atendimento AR Certifast - Maua Centro/SP | H20: =VLOOKUP(G20,Página1!G:L,6,0) -> Ingrid | I20: Aprovado | J20: =Transferencia!L20 -> 290.105.428-58 | K20: =Transferencia!M20 -> 14.338.663/0001-25 | L20: ARENA DE LUTAS ARTES MARCIAIS LTDA
A21: =Transferencia!A21 -> 23029772 | B21: =Transferencia!B21 -> 01/02/2025 | C21: =Transferencia!C21 -> MARCOS FIGUEIRA JAJA | D21: =Transferencia!D21 -> mavilinborges@gmail.com | E21: =Transferencia!G21 -> 5512991279955 | F21: =Transferencia!H21 -> e-CNPJ A1 - PME | G21: =Transferencia!J21 -> PONTO DE ATENDIMENTO AR CERTIFAST - ANDROMEDA/SP | H21: =VLOOKUP(G21,Página1!G:L,6,0) -> Rogério | I21: Aprovado | J21: =Transferencia!L21 -> 199.190.568-80 | K21: =Transferencia!M21 -> 48.790.576/0001-26 | L21: nova sao bernardo negocios imobiliarios ltda
A22: =Transferencia!A22 -> 23030018 | B22: =Transferencia!B22 -> 01/02/2025 | C22: =Transferencia!C22 -> WARLEY GONCALVES DA SILVA | D22: =Transferencia!D22 -> warley.gsilva@yahoo.com.br | E22: =Transferencia!G22 -> 5531988011346 | F22: =Transferencia!H22 -> e-CNPJ A1 - PME | G22: =Transferencia!J22 -> Ponto de Atendimento AR Certifast - Prado BH/MG | H22: =VLOOKUP(G22,Página1!G:L,6,0) -> Isabella | I22: Aprovado | J22: =Transferencia!L22 -> 068.149.256-21 | K22: =Transferencia!M22 -> 53.190.477/0001-43 | L22: CONSORCIO SDT SUL
A23: =Transferencia!A23 -> 23030433 | B23: =Transferencia!B23 -> 01/02/2025 | C23: =Transferencia!C23 -> DEOCLECIO GOMES DO NASCIMENTO | D23: =Transferencia!D23 -> contresult@gmail.com | E23: =Transferencia!G23 -> 5512974014347 | F23: =Transferencia!H23 -> e-PJ A1 - 1 ano | G23: =Transferencia!J23 -> PONTO DE ATENDIMENTO AR CERTIFAST - ANDROMEDA/SP | H23: =VLOOKUP(G23,Página1!G:L,6,0) -> Rogério | I23: Aprovado | J23: =Transferencia!L23 -> 253.457.518-03 | K23: =Transferencia!M23 -> 07.530.477/0001-28 | L23: CONSORCIO DARWIN TB EXTREMO NORTE
A24: =Transferencia!A24 -> 23030865 | B24: =Transferencia!B24 -> 01/02/2025 | C24: =Transferencia!C24 -> RODRIGO MAIA DURANTE | D24: =Transferencia!D24 -> rodrigo@jpcientifica.com.br | E24: =Transferencia!G24 -> 5531991920025 | F24: =Transferencia!H24 -> e-CNPJ A1 - PME | G24: =Transferencia!J24 -> Ponto de Atendimento AR Certifast - Prado BH/MG | H24: =VLOOKUP(G24,Página1!G:L,6,0) -> Isabella | I24: Aprovado | J24: =Transferencia!L24 -> 029.216.446-73 | K24: =Transferencia!M24 -> 49.387.733/0001-10 | L24: CONSORCIO DARWIN TB SAO MIGUEL PAULISTA
A25: =Transferencia!A25 -> 23031487 | B25: =Transferencia!B25 -> 01/02/2025 | C25: =Transferencia!C25 -> PATRICK TEIXEIRA DUARTE | D25: =Transferencia!D25 -> patricktd@gmail.com | E25: =Transferencia!G25 -> 5531993956144 | F25: =Transferencia!H25 -> e-CNPJ A1 - PME | G25: =Transferencia!J25 -> Ponto de Atendimento AR Certifast - Prado BH/MG | H25: =VLOOKUP(G25,Página1!G:L,6,0) -> Isabella | I25: Aprovado | J25: =Transferencia!L25 -> 035.107.876-25 | K25: =Transferencia!M25 -> 37.558.567/0001-98
A26: =Transferencia!A26 -> 19967581 | B26: =Transferencia!B26 -> 02/02/2025 | C26: =Transferencia!C26 -> LETICIA VARIN ANTUNES | D26: =Transferencia!D26 -> leticia.varin@tjmg.jus.br | E26: =Transferencia!G26 -> 5535999664635 | F26: =Transferencia!H26 -> e-CPF A3 - 3 anos | G26: =Transferencia!J26 -> Ponto de Atendimento AR Certifast - Pauliceia/SP - Jus | H26: =VLOOKUP(G26,Página1!G:L,6,0) -> #N/A | I26: Aprovado | J26: =Transferencia!L26 -> 288.413.228-70 | K26: =Transferencia!M26
A27: =Transferencia!A27 -> 20034536 | B27: =Transferencia!B27 -> 02/02/2025 | C27: =Transferencia!C27 -> ANDRE KEIGO YOSHIKAWA | D27: =Transferencia!D27 -> keigo@uol.com.br | E27: =Transferencia!G27 -> 5511994941257 | F27: =Transferencia!H27 -> e-CNPJ A3 - 3 anos | G27: =Transferencia!J27 -> AR Certifast | H27: =VLOOKUP(G27,Página1!G:L,6,0) -> Alexandre | I27: Aprovado | J27: =Transferencia!L27 -> 184.758.198-69 | K27: =Transferencia!M27 -> 00.565.701/0001-78 | L27: 51 568 663 JEFFERSON ALVES DE SOUZA
A28: =Transferencia!A28 -> 20043536 | B28: =Transferencia!B28 -> 03/02/2025 | C28: =Transferencia!C28 -> WALDEMIRO ELIAS MEIRA JUNIOR | D28: =Transferencia!D28 -> ALVES.MEIRA@HOTMAIL.COM | E28: =Transferencia!G28 -> 5566999632858 | F28: =Transferencia!H28 -> e-CNPJ A3 - 3 anos - PME | G28: =Transferencia!J28 -> AR Certifast | H28: =VLOOKUP(G28,Página1!G:L,6,0) -> Alexandre | I28: Aprovado | J28: =Transferencia!L28 -> 862.909.591-15 | K28: =Transferencia!M28 -> 02.590.231/0001-28 | L28: 48 948 530 BARBARA MAIULI DE LIMA KOMATSU
A29: =Transferencia!A29 -> 22949586 | B29: =Transferencia!B29 -> 04/02/2025 | C29: =Transferencia!C29 -> FABIO HENRIQUE DE OLIVEIRA MARTINS | D29: =Transferencia!D29 -> financeiro@onoffmarketing.com.br | E29: =Transferencia!G29 -> 5531987092523 | F29: =Transferencia!H29 -> e-CNPJ A1 - PME | G29: =Transferencia!J29 -> Ponto de Atendimento AR Certifast - Prado BH/MG | H29: =VLOOKUP(G29,Página1!G:L,6,0) -> Isabella | I29: Aprovado | J29: =Transferencia!L29 -> 067.812.186-97 | K29: =Transferencia!M29 -> 21.491.555/0001-53
A30: =Transferencia!A30 -> 22976869 | B30: =Transferencia!B30 -> 04/02/2025 | C30: =Transferencia!C30 -> DOUGLAS MICHAEL SIMMONS | D30: =Transferencia!D30 -> contabilidade@afccontabilsjc.com.br | E30: =Transferencia!G30 -> 5512991726007 | F30: =Transferencia!H30 -> e-CNPJ A1 - PME | G30: =Transferencia!J30 -> PONTO DE ATENDIMENTO AR CERTIFAST - ANDROMEDA/SP | H30: =VLOOKUP(G30,Página1!G:L,6,0) -> Rogério | I30: Aprovado | J30: =Transferencia!L30 -> 236.078.878-70 | K30: =Transferencia!M30 -> 30.990.328/0001-63 | L30: WILSON PICCOLI RECICLAGEM LTDA
A31: =Transferencia!A31 -> 23000842 | B31: =Transferencia!B31 -> 04/02/2025 | C31: =Transferencia!C31 -> PAULO HENRIQUE DOMINGUES SARAIVA | D31: =Transferencia!D31 -> controladoria@accmg.com.br | E31: =Transferencia!G31 -> 5531991731289 | F31: =Transferencia!H31 -> e-CNPJ A1 - 1 ano | G31: =Transferencia!J31 -> Ponto de Atendimento AR Certifast - Prado BH/MG | H31: =VLOOKUP(G31,Página1!G:L,6,0) -> Isabella | I31: Aprovado | J31: =Transferencia!L31 -> 048.132.836-08 | K31: =Transferencia!M31 -> 08.000.185/0001-46 | L31: HLA PARTICIPACOES LTDA
A32: =Transferencia!A32 -> 23003039 | B32: =Transferencia!B32 -> 04/02/2025 | C32: =Transferencia!C32 -> ROSIMEIRA IRMA DO NASCIMENTO MARTAURO | D32: =Transferencia!D32 -> coord.societario@reluzcontabil.com.br | E32: =Transferencia!G32 -> 5511982234577 | F32: =Transferencia!H32 -> e-CNPJ A1 - PME | G32: =Transferencia!J32 -> Ponto de Atendimento AR Certifast - Maua Centro/SP | H32: =VLOOKUP(G32,Página1!G:L,6,0) -> Ingrid | I32: Aprovado | J32: =Transferencia!L32 -> 178.482.678-22 | K32: =Transferencia!M32 -> 34.551.599/0001-73 | L32: GELLI E ABREU COMERCIO DE COLCHOES LTDA
A33: =Transferencia!A33 -> 23009603 | B33: =Transferencia!B33 -> 04/02/2025 | C33: =Transferencia!C33 -> MARIA CRISTINA SIMOES SILVERIO | D33: =Transferencia!D33 -> contabilidade@afccontabilsjc.com.br | E33: =Transferencia!G33 -> 5512988301250 | F33: =Transferencia!H33 -> e-CNPJ A1 - PME | G33: =Transferencia!J33 -> PONTO DE ATENDIMENTO AR CERTIFAST - ANDROMEDA/SP | H33: =VLOOKUP(G33,Página1!G:L,6,0) -> Rogério | I33: Aprovado | J33: =Transferencia!L33 -> 479.570.696-49 | K33: =Transferencia!M33 -> 22.690.586/0001-04 | L33: BEIRA RIO COMERCIO E SERVICOS LTDA
A34: =Transferencia!A34 -> 23015299 | B34: =Transferencia!B34 -> 04/02/2025 | C34: =Transferencia!C34 -> NAGIBA EL JALIS | D34: =Transferencia!D34 -> contabilidade@afccontabilsjc.com.br | E34: =Transferencia!G34 -> 5512991209254 | F34: =Transferencia!H34 -> e-CNPJ A1 - PME | G34: =Transferencia!J34 -> PONTO DE ATENDIMENTO AR CERTIFAST - ANDROMEDA/SP | H34: =VLOOKUP(G34,Página1!G:L,6,0) -> Rogério | I34: Aprovado | J34: =Transferencia!L34 -> 624.789.158-04 | K34: =Transferencia!M34 -> 60.074.234/0001-05 | L34: RIVERSIDE HOLDING BUSSINESS AND PARTICIPATIONS LT
A35: =Transferencia!A35 -> 23021471 | B35: =Transferencia!B35 -> 04/02/2025 | C35: =Transferencia!C35 -> GUILHERME DE CARVALHO LOURES | D35: =Transferencia!D35 -> coord.societario@reluzcontabil.com.br | E35: =Transferencia!G35 -> 5511952377440 | F35: =Transferencia!H35 -> e-CNPJ A1 - PME | G35: =Transferencia!J35 -> Ponto de Atendimento AR Certifast - Maua Centro/SP | H35: =VLOOKUP(G35,Página1!G:L,6,0) -> Ingrid | I35: Aprovado | J35: =Transferencia!L35 -> 480.085.028-27 | K35: =Transferencia!M35 -> 53.704.787/0001-39 | L35: Cosma Do Brasil Produtos e Servicos Automotivos L
A36: =Transferencia!A36 -> 23023341 | B36: =Transferencia!B36 -> 04/02/2025 | C36: =Transferencia!C36 -> VINICIUS GOMES DA SILVA | D36: =Transferencia!D36 -> distribuidorajrmix@gmail.com | E36: =Transferencia!G36 -> 5511946601631 | F36: =Transferencia!H36 -> e-CNPJ A1 - PME | G36: =Transferencia!J36 -> PONTO DE ATENDIMENTO AR CERTIFAST - ANDROMEDA/SP | H36: =VLOOKUP(G36,Página1!G:L,6,0) -> Rogério | I36: Aprovado | J36: =Transferencia!L36 -> 100.928.914-46 | K36: =Transferencia!M36 -> 53.742.281/0001-14
A37: =Transferencia!A37 -> 23025989 | B37: =Transferencia!B37 -> 04/02/2025 | C37: =Transferencia!C37 -> WESLEY VINICIUS ROSA MARTINS | D37: =Transferencia!D37 -> wesley@hortifrutiemporiominas.com.br | E37: =Transferencia!G37 -> 5531984857204 | F37: =Transferencia!H37 -> e-CNPJ A1 - PME | G37: =Transferencia!J37 -> Ponto de Atendimento AR Certifast - Prado BH/MG | H37: =VLOOKUP(G37,Página1!G:L,6,0) -> Isabella | I37: Aprovado | J37: =Transferencia!L37 -> 086.888.796-05 | K37: =Transferencia!M37 -> 35.684.358/0001-65 | L37: LVACP EDUCACIONAL LTDA
A38: =Transferencia!A38 -> 23027405 | B38: =Transferencia!B38 -> 04/02/2025 | C38: =Transferencia!C38 -> FERNANDO DE MOURA GOMES | D38: =Transferencia!D38 -> leandropradoilha@gmail.com | E38: =Transferencia!G38 -> 5512997760065 | F38: =Transferencia!H38 -> e-CNPJ A1 - PME | G38: =Transferencia!J38 -> PONTO DE ATENDIMENTO AR CERTIFAST - ANDROMEDA/SP | H38: =VLOOKUP(G38,Página1!G:L,6,0) -> Rogério | I38: Aprovado | J38: =Transferencia!L38 -> 267.961.728-25 | K38: =Transferencia!M38 -> 43.602.169/0001-24 | L38: GUSTAVO SALVADOR CAMPOS TREINAMENTO
A39: =Transferencia!A39 -> 23030393 | B39: =Transferencia!B39 -> 04/02/2025 | C39: =Transferencia!C39 -> ANA LUIZA GUIMARAES DUARTE | D39: =Transferencia!D39 -> distribuidoraachou@gmail.com | E39: =Transferencia!G39 -> 5531988366384 | F39: =Transferencia!H39 -> e-CNPJ A1 - PME | G39: =Transferencia!J39 -> Ponto de Atendimento AR Certifast - Prado BH/MG | H39: =VLOOKUP(G39,Página1!G:L,6,0) -> Isabella | I39: Aprovado | J39: =Transferencia!L39 -> 139.406.646-50 | K39: =Transferencia!M39 -> 40.488.107/0001-45 | L39: 50 328 212 NATHALIA LOPES DA SILVA
A40: =Transferencia!A40 -> 23031428 | B40: =Transferencia!B40 -> 04/02/2025 | C40: =Transferencia!C40 -> JOSE CARLOS DE OLIVEIRA MONTEIRO | D40: =Transferencia!D40 -> arteemvidrosvdrr@gmail.com | E40: =Transferencia!G40 -> 5512991279045 | F40: =Transferencia!H40 -> e-CNPJ A1 - PME | G40: =Transferencia!J40 -> PONTO DE ATENDIMENTO AR CERTIFAST - ANDROMEDA/SP | H40: =VLOOKUP(G40,Página1!G:L,6,0) -> Rogério | I40: Aprovado | J40: =Transferencia!L40 -> 032.724.478-06 | K40: =Transferencia!M40 -> 06.998.055/0001-19 | L40: 42 658 348 VINICIUS ROBERTO DE OLIVEIRA GOMES
...

Sheet Transferencia
A1: Pedido | B1: Data de Vencimento | C1: Cliente | D1: Email | E1: Numero | F1: DDD | G1: Telefone | H1: Produto | I1: AR | J1: Ponto de Atendimento | K1: Status do Pedido | L1: CPF | M1: CNPJ | N1: Razão Social
A2: 19993515 | B2: 01/02/2025 | C2: GUSTAVO CORONADO SILVA | D2: DANUSIA@SMCONSUL.COM.BR | E2: 11940346464 | F2: 55 | G2: =CONCATENATE(F2,E2) -> 5511940346464 | H2: e-CNPJ A3 - 3 anos - PME | I2: AR CERTIFAST | J2: Ponto de Atendimento AR Certifast - Pauliceia/SP | K2: Aprovado | L2: 487.045.518-85 | M2: 24.020.767/0001-40 | N2: GMUD SERVICOS E INFORMATICA EIRELI
A3: 19998399 | B3: 01/02/2025 | C3: ISABELA PORTO NASCIMENTO | D3: isabela.nascimento@tjmg.jus.br | E3: 31975539005 | F3: 55 | G3: =CONCATENATE(F3,E3) -> 5531975539005 | H3: e-CPF A3 - 3 anos | I3: AR CERTIFAST | J3: Ponto de Atendimento AR Certifast - Prado BH/MG - JUS | K3: Aprovado | L3: 874.483.271-00
A4: 20008751 | B4: 01/02/2025 | C4: CLAUDIO LUIZ CARVALHO SOUZA | D4: claudio@engenhariapower.com.br | E4: 1230185487 | F4: 55 | G4: =CONCATENATE(F4,E4) -> 551230185487 | H4: e-CPF A3 - 3 anos | I4: AR CERTIFAST | J4: PONTO DE ATENDIMENTO AR CERTIFAST - ANDROMEDA/SP | K4: Aprovado | L4: 027.312.736-58
A5: 22904676 | B5: 01/02/2025 | C5: EDMUNDO MARIANO DA COSTA LANNA | D5: contabilidade@cimcop.com.br | E5: 31991665091 | F5: 55 | G5: =CONCATENATE(F5,E5) -> 5531991665091 | H5: e-CNPJ A1 - 1 ano | I5: AR CERTIFAST | J5: Ponto de Atendimento AR Certifast - Prado BH/MG | K5: Aprovado | L5: 522.536.866-20 | M5: 17.161.464/0001-82 | N5: CIMCOP S A ENGENHARIA E CONSTRUCOES
A6: 22925222 | B6: 01/02/2025 | C6: MARIA GISELE CRUZ ANDRADE | D6: adm.monteferragens@gmail.com | E6: 11939391930 | F6: 55 | G6: =CONCATENATE(F6,E6) -> 5511939391930 | H6: e-CNPJ A1 - 1 ano | I6: AR CERTIFAST | J6: Ponto de Atendimento AR Certifast - Maua Centro/SP | K6: Aprovado | L6: 401.065.218-70 | M6: 49.393.402/0001-92 | N6: MONTE FERRAGENS LTDA
A7: 22978910 | B7: 01/02/2025 | C7: RAFAEL RODRIGUES DE MELO | D7: jh.contabilidade@hotmail.com | E7: 11984111572 | F7: 55 | G7: =CONCATENATE(F7,E7) -> 5511984111572 | H7: e-CNPJ A1 - PME | I7: AR CERTIFAST | J7: PONTO DE ATENDIMENTO AR CERTIFAST - ANDROMEDA/SP | K7: Aprovado | L7: 348.833.098-27 | M7: 53.594.729/0001-08 | N7: REV COLCHOES LTDA
A8: 23000204 | B8: 01/02/2025 | C8: WALTER SILVEIRA | D8: coord.societario@reluzcontabil.com.br | E8: 11998586363 | F8: 55 | G8: =CONCATENATE(F8,E8) -> 5511998586363 | H8: e-CNPJ A1 - PME | I8: AR CERTIFAST | J8: Ponto de Atendimento AR Certifast - Maua Centro/SP | K8: Aprovado | L8: 614.447.588-53 | M8: 39.378.578/0002-00 | N8: ACONGA SANDALIAS E ACESSORIOS DO VESTUARIO LTDA
A9: 23005642 | B9: 01/02/2025 | C9: EMERSON LUIS TEIXEIRA | D9: brenda.bulgarelli@biocontabil.com.br | E9: 11996005678 | F9: 55 | G9: =CONCATENATE(F9,E9) -> 5511996005678 | H9: e-CNPJ A1 - PME | I9: AR CERTIFAST | J9: PONTO DE ATENDIMENTO AR CERTIFAST - ANDROMEDA/SP | K9: Aprovado | L9: 139.953.418-10 | M9: 19.005.929/0001-31 | N9: LUIZA VALENTINE AMBIENTES PLANEJADOS LTDA
A10: 23009504 | B10: 01/02/2025 | C10: ADALBERTO FERREIRA FILHO | D10: brun31ma@terra.com.br | F10: 55 | G10: =CONCATENATE(F10,E10) -> 55 | H10: e-CNPJ A1 - PME | I10: AR CERTIFAST | J10: Ponto de Atendimento AR Certifast - Maua Centro/SP | K10: Aprovado | L10: 008.226.258-65 | M10: 35.524.722/0001-20 | N10: QUALIDADE AQUI IMPORTACAO E COMERCIO DE ARTIGOS D
A11: 23013368 | B11: 01/02/2025 | C11: HUGO CARDOSO GONCALVES PEREIRA | D11: goncalves.hugo@outlook.com | E11: 11949407981 | F11: 55 | G11: =CONCATENATE(F11,E11) -> 5511949407981 | H11: e-CNPJ A1 - 1 ano | I11: AR CERTIFAST | J11: Ponto de Atendimento AR Certifast - Maua Centro/SP | K11: Aprovado | L11: 403.679.028-50 | M11: 37.403.134/0001-63 | N11: HUGO CARDOSO GONCALVES PEREIRA
A12: 23014736 | B12: 01/02/2025 | C12: DAYANE ONILES BATISTA DA SILVA | D12: dayane.obs@gmail.com | F12: 55 | G12: =CONCATENATE(F12,E12) -> 55 | H12: e-CNPJ A1 - 1 ano | I12: AR CERTIFAST | J12: Ponto de Atendimento AR Certifast - Maua Centro/SP | K12: Aprovado | L12: 375.947.258-32 | M12: 46.138.623/0001-26 | N12: ALFRED E CONCIERGE TECH SOLUTIONS LTDA
A13: 23018988 | B13: 01/02/2025 | C13: ALBERTO SIQUEIRA FERREIRA | D13: albertosq@gmail.com | F13: 55 | G13: =CONCATENATE(F13,E13) -> 55 | H13: e-CNPJ A1 - PME | I13: AR CERTIFAST | J13: Ponto de Atendimento AR Certifast - Maua Centro/SP | K13: Aprovado | L13: 377.932.518-73 | M13: 37.005.872/0001-52 | N13: ALBERTO SIQUEIRA FERREIRA 37793251873
A14: 23021199 | B14: 01/02/2025 | C14: AGENILTO ALVES DA CRUZ | D14: coord.societario@reluzcontabil.com.br | E14: 11971486400 | F14: 55 | G14: =CONCATENATE(F14,E14) -> 5511971486400 | H14: e-CPF A1 - 1 ano | I14: AR CERTIFAST | J14: Ponto de Atendimento AR Certifast - Maua Centro/SP | K14: Aprovado | L14: 182.969.108-29
A15: 23022711 | B15: 01/02/2025 | C15: ANA PAULA OJEDA DE OLIVEIRA | D15: coord.societario@reluzcontabil.com.br | E15: 11911445032 | F15: 55 | G15: =CONCATENATE(F15,E15) -> 5511911445032 | H15: e-CPF A1 - 1 ano | I15: AR CERTIFAST | J15: Ponto de Atendimento AR Certifast - Maua Centro/SP | K15: Aprovado | L15: 221.613.368-00
A16: 23023472 | B16: 01/02/2025 | C16: MARCEL SANT ANA GUARIENTE | D16: marcel.guariente@gmail.com | F16: 55 | G16: =CONCATENATE(F16,E16) -> 55 | H16: e-CPF A1 - 1 ano | I16: AR CERTIFAST | J16: Ponto de Atendimento AR Certifast - Maua Centro/SP | K16: Aprovado | L16: 410.216.078-78
A17: 23026458 | B17: 01/02/2025 | C17: ADALTO LOURENCO SANTOS | D17: coord.societario@reluzcontabil.com.br | E17: 13997174553 | F17: 55 | G17: =CONCATENATE(F17,E17) -> 5513997174553 | H17: e-CNPJ A1 - PME | I17: AR CERTIFAST | J17: Ponto de Atendimento AR Certifast - Maua Centro/SP | K17: Aprovado | L17: 289.509.778-00 | M17: 32.147.600/0001-73 | N17: A L SANTOS TRANSPORTES E LOCACAO LTDA
A18: 23026909 | B18: 01/02/2025 | C18: GISLAINE MARTINS | D18: contabilidade2@escritoriocontabiletica.com.br | F18: 55 | G18: =CONCATENATE(F18,E18) -> 55 | H18: e-CNPJ A1 - 1 ano | I18: AR CERTIFAST | J18: Ponto de Atendimento AR Certifast - Maua Centro/SP | K18: Aprovado | L18: 170.433.338-57 | M18: 10.994.130/0001-40 | N18: HOUSE SP PARTICIPACOES PROMOTORA DE VENDAS LTDA
A19: 23027103 | B19: 01/02/2025 | C19: JOSE FABIO NETTO PARENTONI | D19: henriquepedrosa@madeplan.com.br | E19: 31989014897 | F19: 55 | G19: =CONCATENATE(F19,E19) -> 5531989014897 | H19: e-CNPJ A1 - 1 ano | I19: AR CERTIFAST | J19: Ponto de Atendimento AR Certifast - Prado BH/MG | K19: Aprovado | L19: 500.784.886-72 | M19: 21.097.712/0001-40 | N19: MADEPLAN MADEIREIRA PLANALTO LIMITADA
A20: 23028744 | B20: 01/02/2025 | C20: LEANDRO CUNHA LOBO | D20: coord.societario@reluzcontabil.com.br | E20: 11947888348 | F20: 55 | G20: =CONCATENATE(F20,E20) -> 5511947888348 | H20: e-CNPJ A1 - PME | I20: AR CERTIFAST | J20: Ponto de Atendimento AR Certifast - Maua Centro/SP | K20: Aprovado | L20: 290.105.428-58 | M20: 14.338.663/0001-25 | N20: BBR LOCADORA DE VEICULOS LTDA
A21: 23029772 | B21: 01/02/2025 | C21: MARCOS FIGUEIRA JAJA | D21: mavilinborges@gmail.com | E21: 12991279955 | F21: 55 | G21: =CONCATENATE(F21,E21) -> 5512991279955 | H21: e-CNPJ A1 - PME | I21: AR CERTIFAST | J21: PONTO DE ATENDIMENTO AR CERTIFAST - ANDROMEDA/SP | K21: Aprovado | L21: 199.190.568-80 | M21: 48.790.576/0001-26 | N21: JAJA S HOUSE LTDA
A22: 23030018 | B22: 01/02/2025 | C22: WARLEY GONCALVES DA SILVA | D22: warley.gsilva@yahoo.com.br | E22: 31988011346 | F22: 55 | G22: =CONCATENATE(F22,E22) -> 5531988011346 | H22: e-CNPJ A1 - PME | I22: AR CERTIFAST | J22: Ponto de Atendimento AR Certifast - Prado BH/MG | K22: Aprovado | L22: 068.149.256-21 | M22: 53.190.477/0001-43 | N22: WARLEY GONCALVES CORRETORA DE SEGUROS LTDA
A23: 23030433 | B23: 01/02/2025 | C23: DEOCLECIO GOMES DO NASCIMENTO | D23: contresult@gmail.com | E23: 12974014347 | F23: 55 | G23: =CONCATENATE(F23,E23) -> 5512974014347 | H23: e-PJ A1 - 1 ano | I23: AR CERTIFAST | J23: PONTO DE ATENDIMENTO AR CERTIFAST - ANDROMEDA/SP | K23: Aprovado | L23: 253.457.518-03 | M23: 07.530.477/0001-28 | N23: D J SOM E ACESSORIOS LTDA
A24: 23030865 | B24: 01/02/2025 | C24: RODRIGO MAIA DURANTE | D24: rodrigo@jpcientifica.com.br | E24: 31991920025 | F24: 55 | G24: =CONCATENATE(F24,E24) -> 5531991920025 | H24: e-CNPJ A1 - PME | I24: AR CERTIFAST | J24: Ponto de Atendimento AR Certifast - Prado BH/MG | K24: Aprovado | L24: 029.216.446-73 | M24: 49.387.733/0001-10 | N24: RODRIGO MAIA REPRESENTACOES LTDA
A25: 23031487 | B25: 01/02/2025 | C25: PATRICK TEIXEIRA DUARTE | D25: patricktd@gmail.com | E25: 31993956144 | F25: 55 | G25: =CONCATENATE(F25,E25) -> 5531993956144 | H25: e-CNPJ A1 - PME | I25: AR CERTIFAST | J25: Ponto de Atendimento AR Certifast - Prado BH/MG | K25: Aprovado | L25: 035.107.876-25 | M25: 37.558.567/0001-98 | N25: NOSSA CASA INTELIGENTE SISTEMAS DE SEGURANCA E SE
A26: 19967581 | B26: 02/02/2025 | C26: LETICIA VARIN ANTUNES | D26: leticia.varin@tjmg.jus.br | E26: 35999664635 | F26: 55 | G26: =CONCATENATE(F26,E26) -> 5535999664635 | H26: e-CPF A3 - 3 anos | I26: AR CERTIFAST | J26: Ponto de Atendimento AR Certifast - Pauliceia/SP - Jus | K26: Aprovado | L26: 288.413.228-70
A27: 20034536 | B27: 02/02/2025 | C27: ANDRE KEIGO YOSHIKAWA | D27: keigo@uol.com.br | E27: 11994941257 | F27: 55 | G27: =CONCATENATE(F27,E27) -> 5511994941257 | H27: e-CNPJ A3 - 3 anos | I27: AR CERTIFAST | J27: AR Certifast | K27: Aprovado | L27: 184.758.198-69 | M27: 00.565.701/0001-78 | N27: JE PROCESSOS DE LIMPEZA S S LTDA
A28: 20043536 | B28: 03/02/2025 | C28: WALDEMIRO ELIAS MEIRA JUNIOR | D28: ALVES.MEIRA@HOTMAIL.COM | E28: 66999632858 | F28: 55 | G28: =CONCATENATE(F28,E28) -> 5566999632858 | H28: e-CNPJ A3 - 3 anos - PME | I28: AR CERTIFAST | J28: AR Certifast | K28: Aprovado | L28: 862.909.591-15 | M28: 02.590.231/0001-28 | N28: BANDEIRANTES COMERCIO DE MATERIAIS DE CONSTRUCAO
A29: 22949586 | B29: 04/02/2025 | C29: FABIO HENRIQUE DE OLIVEIRA MARTINS | D29: financeiro@onoffmarketing.com.br | E29: 31987092523 | F29: 55 | G29: =CONCATENATE(F29,E29) -> 5531987092523 | H29: e-CNPJ A1 - PME | I29: AR CERTIFAST | J29: Ponto de Atendimento AR Certifast - Prado BH/MG | K29: Aprovado | L29: 067.812.186-97 | M29: 21.491.555/0001-53 | N29: FABIO HENRIQUE DE OLIVEIRA MARTINS 06781218697
A30: 22976869 | B30: 04/02/2025 | C30: DOUGLAS MICHAEL SIMMONS | D30: contabilidade@afccontabilsjc.com.br | E30: 12991726007 | F30: 55 | G30: =CONCATENATE(F30,E30) -> 5512991726007 | H30: e-CNPJ A1 - PME | I30: AR CERTIFAST | J30: PONTO DE ATENDIMENTO AR CERTIFAST - ANDROMEDA/SP | K30: Aprovado | L30: 236.078.878-70 | M30: 30.990.328/0001-63 | N30: MEL IDIOMAS LTDA
A31: 23000842 | B31: 04/02/2025 | C31: PAULO HENRIQUE DOMINGUES SARAIVA | D31: controladoria@accmg.com.br | E31: 31991731289 | F31: 55 | G31: =CONCATENATE(F31,E31) -> 5531991731289 | H31: e-CNPJ A1 - 1 ano | I31: AR CERTIFAST | J31: Ponto de Atendimento AR Certifast - Prado BH/MG | K31: Aprovado | L31: 048.132.836-08 | M31: 08.000.185/0001-46 | N31: ACCOUNTANCY CONTABILIDADE E CONSULTORIA LTDA
A32: 23003039 | B32: 04/02/2025 | C32: ROSIMEIRA IRMA DO NASCIMENTO MARTAURO | D32: coord.societario@reluzcontabil.com.br | E32: 11982234577 | F32: 55 | G32: =CONCATENATE(F32,E32) -> 5511982234577 | H32: e-CNPJ A1 - PME | I32: AR CERTIFAST | J32: Ponto de Atendimento AR Certifast - Maua Centro/SP | K32: Aprovado | L32: 178.482.678-22 | M32: 34.551.599/0001-73 | N32: ROSIMEIRA IRMA DO NASCIMENTO MARTAURO
A33: 23009603 | B33: 04/02/2025 | C33: MARIA CRISTINA SIMOES SILVERIO | D33: contabilidade@afccontabilsjc.com.br | E33: 12988301250 | F33: 55 | G33: =CONCATENATE(F33,E33) -> 5512988301250 | H33: e-CNPJ A1 - PME | I33: AR CERTIFAST | J33: PONTO DE ATENDIMENTO AR CERTIFAST - ANDROMEDA/SP | K33: Aprovado | L33: 479.570.696-49 | M33: 22.690.586/0001-04 | N33: M C S SILVERIO POSTE PADRAO
A34: 23015299 | B34: 04/02/2025 | C34: NAGIBA EL JALIS | D34: contabilidade@afccontabilsjc.com.br | E34: 12991209254 | F34: 55 | G34: =CONCATENATE(F34,E34) -> 5512991209254 | H34: e-CNPJ A1 - PME | I34: AR CERTIFAST | J34: PONTO DE ATENDIMENTO AR CERTIFAST - ANDROMEDA/SP | K34: Aprovado | L34: 624.789.158-04 | M34: 60.074.234/0001-05 | N34: 60 074 234 NAGIBA EL JALIS
A35: 23021471 | B35: 04/02/2025 | C35: GUILHERME DE CARVALHO LOURES | D35: coord.societario@reluzcontabil.com.br | E35: 11952377440 | F35: 55 | G35: =CONCATENATE(F35,E35) -> 5511952377440 | H35: e-CNPJ A1 - PME | I35: AR CERTIFAST | J35: Ponto de Atendimento AR Certifast - Maua Centro/SP | K35: Aprovado | L35: 480.085.028-27 | M35: 53.704.787/0001-39 | N35: VD REPRESENTACOES E CONSULTORIA EMPRESARIAL LTDA
A36: 23023341 | B36: 04/02/2025 | C36: VINICIUS GOMES DA SILVA | D36: distribuidorajrmix@gmail.com | E36: 11946601631 | F36: 55 | G36: =CONCATENATE(F36,E36) -> 5511946601631 | H36: e-CNPJ A1 - PME | I36: AR CERTIFAST | J36: PONTO DE ATENDIMENTO AR CERTIFAST - ANDROMEDA/SP | K36: Aprovado | L36: 100.928.914-46 | M36: 53.742.281/0001-14 | N36: 53 742 281 VINICIUS GOMES DA SILVA
A37: 23025989 | B37: 04/02/2025 | C37: WESLEY VINICIUS ROSA MARTINS | D37: wesley@hortifrutiemporiominas.com.br | E37: 31984857204 | F37: 55 | G37: =CONCATENATE(F37,E37) -> 5531984857204 | H37: e-CNPJ A1 - PME | I37: AR CERTIFAST | J37: Ponto de Atendimento AR Certifast - Prado BH/MG | K37: Aprovado | L37: 086.888.796-05 | M37: 35.684.358/0001-65 | N37: WVRM ACESSORIA LTDA
A38: 23027405 | B38: 04/02/2025 | C38: FERNANDO DE MOURA GOMES | D38: leandropradoilha@gmail.com | E38: 12997760065 | F38: 55 | G38: =CONCATENATE(F38,E38) -> 5512997760065 | H38: e-CNPJ A1 - PME | I38: AR CERTIFAST | J38: PONTO DE ATENDIMENTO AR CERTIFAST - ANDROMEDA/SP | K38: Aprovado | L38: 267.961.728-25 | M38: 43.602.169/0001-24 | N38: ILLA RESTAURANTE E ENTRETENIMENTO LTDA
... A41: 23031939 | B41: 04/02/2025 | C41: EMERSON ALVES RIBEIRO | D41: coord.societario@reluzcontabil.com.br | E41: 11997706778 | F41: 55 | G41: =CONCATENATE(F41,E41) -> 5511997706778 | H41: e-CNPJ A1 - PME | I41: AR CERTIFAST | J41: Ponto de Atendimento AR Certifast - Maua Centro/SP | K41: Aprovado | L41: 787.894.515-20 | M41: 10.762.665/0001-96 | N41: HOLD SCIENTIFIC IMPORTACAO E EXPORTACAO LTDA
A42: 23034356 | B42: 04/02/2025 | C42: DJALMA AFONSO VIEIRA | D42: bless.assessoria@gmail.com | F42: 55 | G42: =CONCATENATE(F42,E42) -> 55 | H42: e-CNPJ A1 - PME | I42: AR CERTIFAST | J42: Ponto de Atendimento AR Certifast - Maua Centro/SP | K42: Aprovado | L42: 097.224.538-31 | M42: 49.422.269/0001-55 | N42: DISTRIBUIDORA DE ALIMENTOS FLOR DO IPE LTDA
...

Sheet Página1
A1: =IFERROR(__xludf.DUMMYFUNCTION("UNIQUE(Folha3!F:F,FALSE,FALSE)"),"Produto") -> Produto | O1: =IFERROR(__xludf.DUMMYFUNCTION("UNIQUE(Folha3!H:H,FALSE,FALSE)"),"Ponto de Atendimento") -> Ponto de Atendimento
A2: =IFERROR(__xludf.DUMMYFUNCTION("""COMPUTED_VALUE"""),"e-CNPJ A3") -> e-CNPJ A3 | G2: Ponto de Atendimento | O2: =IFERROR(__xludf.DUMMYFUNCTION("""COMPUTED_VALUE"""),"Ponto de Atendimento AR Certifast - Maua Centro/SP") -> Ponto de Atendimento AR Certifast - Maua Centro/SP
A3: =IFERROR(__xludf.DUMMYFUNCTION("""COMPUTED_VALUE"""),"e-CPF A3") -> e-CPF A3 | G3: Ponto de Atendimento AR Certifast - Maua Centro/SP | L3: Ingrid | O3: =IFERROR(__xludf.DUMMYFUNCTION("""COMPUTED_VALUE"""),"Ponto de Atendimento AR Certifast - Prado BH/MG") -> Ponto de Atendimento AR Certifast - Prado BH/MG
A4: =IFERROR(__xludf.DUMMYFUNCTION("""COMPUTED_VALUE"""),"e-CPF A1") -> e-CPF A1 | G4: Ponto de Atendimento AR Certifast - Prado BH/MG | L4: Isabella | O4: =IFERROR(__xludf.DUMMYFUNCTION("""COMPUTED_VALUE"""),"AR Certifast") -> AR Certifast
A5: =IFERROR(__xludf.DUMMYFUNCTION("""COMPUTED_VALUE"""),"e-CNPJ A1") -> e-CNPJ A1 | G5: AR Certifast | L5: Alexandre | O5: =IFERROR(__xludf.DUMMYFUNCTION("""COMPUTED_VALUE"""),"PONTO DE ATENDIMENTO AR CERTIFAST - ANDROMEDA/SP") -> PONTO DE ATENDIMENTO AR CERTIFAST - ANDROMEDA/SP
G6: PONTO DE ATENDIMENTO AR CERTIFAST - ANDROMEDA/SP | L6: Rogério | O6: =IFERROR(__xludf.DUMMYFUNCTION("""COMPUTED_VALUE"""),"Ponto de Atendimento AR Certifast - Pauliceia/SP") -> Ponto de Atendimento AR Certifast - Pauliceia/SP
G7: Ponto de Atendimento AR Certifast - Pauliceia/SP | L7: Alexandre | O7: =IFERROR(__xludf.DUMMYFUNCTION("""COMPUTED_VALUE"""),"PONTO DE ATENDIMENTO AR CERTIFAST - CARIJOS - STA/SP") -> PONTO DE ATENDIMENTO AR CERTIFAST - CARIJOS - STA/SP
G8: PONTO DE ATENDIMENTO AR CERTIFAST - CARIJOS - STA/SP | L8: Alexandre | O8: =IFERROR(__xludf.DUMMYFUNCTION("""COMPUTED_VALUE"""),"Ponto de Atendimento AR Certifast - Galeria Nova Barao - Edificio 3/SP") -> Ponto de Atendimento AR Certifast - Galeria Nova Barao - Edificio 3/SP
G9: Ponto de Atendimento AR Certifast - Galeria Nova Barao - Edificio 3/SP | L9: Alexandre | O9: =IFERROR(__xludf.DUMMYFUNCTION("""COMPUTED_VALUE"""),"PONTO DE ATENDIMENTO AR CERTIFAST - ILHABELA/SP") -> PONTO DE ATENDIMENTO AR CERTIFAST - ILHABELA/SP
G10: PONTO DE ATENDIMENTO AR CERTIFAST - ILHABELA/SP | L10: Leandro | O10: =IFERROR(__xludf.DUMMYFUNCTION("""COMPUTED_VALUE"""),"Ponto de Atendimento AR Certifast - Prado BH/MG - JUS") -> Ponto de Atendimento AR Certifast - Prado BH/MG - JUS
G11: Ponto de Atendimento AR Certifast - Prado BH/MG - JUS | L11: Isabella | O11: =IFERROR(__xludf.DUMMYFUNCTION("""COMPUTED_VALUE"""),"PONTO DE ATENDIMENTO AR Certifast - Sao Jose dos Campos/SP") -> PONTO DE ATENDIMENTO AR Certifast - Sao Jose dos Campos/SP
G12: PONTO DE ATENDIMENTO AR Certifast - Sao Jose dos Campos/SP | L12: Rafael | O12: =IFERROR(__xludf.DUMMYFUNCTION("""COMPUTED_VALUE"""),"PONTO DE ATENDIMENTO AR CERTIFAST - ANDROMEDA/SP - JUS") -> PONTO DE ATENDIMENTO AR CERTIFAST - ANDROMEDA/SP - JUS
G13: PONTO DE ATENDIMENTO AR CERTIFAST - ANDROMEDA/SP - JUS | L13: Rogério | O13: =IFERROR(__xludf.DUMMYFUNCTION("""COMPUTED_VALUE"""),"AR Certifast - Jus") -> AR Certifast - Jus
G14: AR Certifast - Jus | L14: Alexandre | O14: =IFERROR(__xludf.DUMMYFUNCTION("""COMPUTED_VALUE"""),"Ponto de Atendimento AR Certifast - Maua Centro/SP - Jus") -> Ponto de Atendimento AR Certifast - Maua Centro/SP - Jus
G15: Ponto de Atendimento AR Certifast - Maua Centro/SP - Jus | L15: Ingrid | O15: =IFERROR(__xludf.DUMMYFUNCTION("""COMPUTED_VALUE"""),"Ponto de Atendimento AR Certifast - Jundiai Centro/SP") -> Ponto de Atendimento AR Certifast - Jundiai Centro/SP
G16: Ponto de Atendimento AR Certifast - Jundiai Centro/SP | L16: Alexandre | O16: =IFERROR(__xludf.DUMMYFUNCTION("""COMPUTED_VALUE"""),"Ponto de Atendimento AR Certifast - Galeria Nova Barao - Edificio 3/SP - Jus") -> Ponto de Atendimento AR Certifast - Galeria Nova Barao - Edificio 3/SP - Jus
G17: Ponto de Atendimento AR Certifast - Galeria Nova Barao - Edificio 3/SP - Jus | L17: Alexandre
